El bloque `try...catch` en Node.js (y en JavaScript en general) es una estructura utilizada para manejar excepciones o errores en el código. Aquí hay una explicación detallada:

- **`try`**: El bloque `try` se utiliza para rodear el código que se espera pueda lanzar una excepción. Cuando ocurre una excepción dentro de este bloque, la ejecución del código se detiene en ese punto y se pasa al bloque `catch`.

- **`catch`**: El bloque `catch` se utiliza para manejar la excepción que se produjo dentro del bloque `try`. Puedes acceder al objeto de la excepción y tomar medidas para gestionarla, como registrar un mensaje de error o realizar una acción específica.

Un ejemplo sencillo en Node.js:

```javascript
try {
  // Código que puede lanzar una excepción
  const resultado = 10 / 0; // Esto lanzará una excepción de división por cero
  console.log(resultado); // Esta línea nunca se ejecutará
} catch (error) {
  // Manejar la excepción
  console.error('Se ha producido un error:', error.message);
}
```

En este ejemplo, el código intenta dividir 10 por 0, lo que resultará en una excepción de "División por cero". La excepción se captura en el bloque `catch`, y se imprime un mensaje de error en la consola.

El uso de `try...catch` es fundamental para manejar errores de manera controlada en tus aplicaciones Node.js. Te permite detectar excepciones, registrarlas y tomar medidas adecuadas para garantizar que tu aplicación no se bloquee debido a un error inesperado. Puedes personalizar la forma en que manejas las excepciones según tus necesidades, lo que es esencial para escribir aplicaciones robustas y fiables.